fixing async tests. looks like if we are not reading result of Future.get it will not always throw exception, even when it should. sounds ridiculus doesn't it?

