fix(auth): exception created by not thrown

